Workbook

Sheet 📚 Study Plan
A1: 🎯 ASP.NET Core Web API — Complete Study Plan
A2: 📅 Start: 18-May-2026 | End: 22-Jun-2026 | Total Topics: 176 | Total Days: 36 | F2: Daily Target: 5 Topics/Day ⚡ Update Status column after each topic →
A3: STATUS: ✅ Done 🔄 In Progress ⏸ Paused ❌ Skipped ⬜ Not Started
B4: # | C4: Section | D4: Topic | E4: Date | F4: Day | G4: T# | H4: Status | I4: Notes
A5: 📅 Day 1 — Monday, 18 May 2026 · Topics 1 – 5
B6: 1 | C6: ASP.NET Core Web API – Basics | D6: Introduction to ASP.NET Core Web API | E6: 18-May-2026 | F6: 1 | G6: 1/5 | H6: ✅ Done
B7: 2 | C7: ASP.NET Core Web API – Basics | D7: HTTP (HyperText Transport Protocol) | E7: 18-May-2026 | F7: 1 | G7: 2/5 | H7: ✅ Done
B8: 3 | C8: ASP.NET Core Web API – Basics | D8: Creating ASP.NET Core Web API Project using .NET Core CLI | E8: 18-May-2026 | F8: 1 | G8: 3/5 | H8: ⬜ Not Started
B9: 4 | C9: ASP.NET Core Web API – Basics | D9: How to Test ASP.NET Core Web API Using Postman | E9: 18-May-2026 | F9: 1 | G9: 4/5 | H9: ⬜ Not Started
B10: 5 | C10: ASP.NET Core Web API – Basics | D10: Creating ASP.NET Core Web API Project in Visual Studio | E10: 18-May-2026 | F10: 1 | G10: 5/5 | H10: ⬜ Not Started
A11: 📅 Day 2 — Tuesday, 19 May 2026 · Topics 6 – 10
B12: 6 | C12: ASP.NET Core Web API – Basics | D12: Default ASP.NET Core Web API Files and Folders | E12: 19-May-2026 | F12: 2 | G12: 1/5 | H12: ⬜ Not Started
B13: 7 | C13: ASP.NET Core Web API – Basics | D13: ASP.NET Core Web API Project File | E13: 19-May-2026 | F13: 2 | G13: 2/5 | H13: ⬜ Not Started
B14: 8 | C14: ASP.NET Core Web API – Basics | D14: ASP.NET Core Web API Main Method | E14: 19-May-2026 | F14: 2 | G14: 3/5 | H14: ⬜ Not Started
B15: 9 | C15: ASP.NET Core Web API – Basics | D15: Controllers in ASP.NET Core Web API | E15: 19-May-2026 | F15: 2 | G15: 4/5 | H15: ⬜ Not Started
B16: 10 | C16: ASP.NET Core Web API – Basics | D16: Models in ASP.NET Core Web API | E16: 19-May-2026 | F16: 2 | G16: 5/5 | H16: ⬜ Not Started
A17: 📅 Day 3 — Wednesday, 20 May 2026 · Topics 11 – 15
B18: 11 | C18: ASP.NET Core Web API – Basics | D18: Services in ASP.NET Core Web API | E18: 20-May-2026 | F18: 3 | G18: 1/5 | H18: ⬜ Not Started
B19: 12 | C19: ASP.NET Core Web API – Basics | D19: ASP.NET Core Web API AppSettings.json file | E19: 20-May-2026 | F19: 3 | G19: 2/5 | H19: ⬜ Not Started
B20: 13 | C20: ASP.NET Core Web API – Basics | D20: ASP.NET Core In-Process Hosting Model | E20: 20-May-2026 | F20: 3 | G20: 3/5 | H20: ⬜ Not Started
B21: 14 | C21: ASP.NET Core Web API – Basics | D21: ASP.NET Core Kestrel Web Server | E21: 20-May-2026 | F21: 3 | G21: 4/5 | H21: ⬜ Not Started
B22: 15 | C22: ASP.NET Core Web API – Basics | D22: ASP.NET Core Out of Process Hosting Model | E22: 20-May-2026 | F22: 3 | G22: 5/5 | H22: ⬜ Not Started
A23: 📅 Day 4 — Thursday, 21 May 2026 · Topics 16 – 20
B24: 16 | C24: ASP.NET Core Web API – Basics | D24: Hosting Model Interview Questions and Answers | E24: 21-May-2026 | F24: 4 | G24: 1/5 | H24: ⬜ Not Started
B25: 17 | C25: ASP.NET Core Web API – Basics | D25: Dependency Injection in ASP.NET Core Web API | E25: 21-May-2026 | F25: 4 | G25: 2/5 | H25: ⬜ Not Started
B26: 18 | C26: ASP.NET Core Web API – Basics | D26: Singleton vs Scoped vs Transient in ASP.NET Core Web API | E26: 21-May-2026 | F26: 4 | G26: 3/5 | H26: ⬜ Not Started
B27: 19 | C27: ASP.NET Core Web API – Basics | D27: Swagger API in ASP.NET Core Web API | E27: 21-May-2026 | F27: 4 | G27: 4/5 | H27: ⬜ Not Started
B28: 20 | C28: ASP.NET Core Web API – Routing | D28: Routing in ASP.NET Core Web API | E28: 21-May-2026 | F28: 4 | G28: 5/5 | H28: ⬜ Not Started
A29: 📅 Day 5 — Friday, 22 May 2026 · Topics 21 – 25
B30: 21 | C30: ASP.NET Core Web API – Routing | D30: Route Parameters and Query Strings in Routing | E30: 22-May-2026 | F30: 5 | G30: 1/5 | H30: ⬜ Not Started
B31: 22 | C31: ASP.NET Core Web API – Routing | D31: Multiple URLs for a Single Resource in ASP.NET Core Web API | E31: 22-May-2026 | F31: 5 | G31: 2/5 | H31: ⬜ Not Started
B32: 23 | C32: ASP.NET Core Web API – Routing | D32: Token Replacement in ASP.NET Core Web API | E32: 22-May-2026 | F32: 5 | G32: 3/5 | H32: ⬜ Not Started
B33: 24 | C33: ASP.NET Core Web API – Routing | D33: Route Prefix in ASP.NET Core Web API | E33: 22-May-2026 | F33: 5 | G33: 4/5 | H33: ⬜ Not Started
B34: 25 | C34: ASP.NET Core Web API – Routing | D34: Route Constraints in ASP.NET Core Web API | E34: 22-May-2026 | F34: 5 | G34: 5/5 | H34: ⬜ Not Started
A35: 📅 Day 6 — Saturday, 23 May 2026 · Topics 26 – 30
B36: 26 | C36: ASP.NET Core Web API – Routing | D36: How Routing Works in ASP.NET Core Web API | E36: 23-May-2026 | F36: 6 | G36: 1/5 | H36: ⬜ Not Started
B37: 27 | C37: ASP.NET Core Web API – Return Types and Status Codes | D37: Action Return Types in ASP.NET Core Web API | E37: 23-May-2026 | F37: 6 | G37: 2/5 | H37: ⬜ Not Started
B38: 28 | C38: ASP.NET Core Web API – Return Types and Status Codes | D38: HTTP Status Codes in ASP.NET Core Web API | E38: 23-May-2026 | F38: 6 | G38: 3/5 | H38: ⬜ Not Started
B39: 29 | C39: ASP.NET Core Web API – Return Types and Status Codes | D39: 200 HTTP Status Code in ASP.NET Core Web API | E39: 23-May-2026 | F39: 6 | G39: 4/5 | H39: ⬜ Not Started
B40: 30 | C40: ASP.NET Core Web API – Return Types and Status Codes | D40: 201 HTTP Status Code in ASP.NET Core Web API | E40: 23-May-2026 | F40: 6 | G40: 5/5 | H40: ⬜ Not Started
...

Sheet 📊 Dashboard
A1: 📊 ASP.NET Core Web API — Progress Dashboard
C4: TOTAL TOPICS | E4: ✅ DONE | G4: 🔄 IN PROGRESS | I4: ⬜ REMAINING
C6: 176 | E6: =COUNTIF('📚 Study Plan'!H:H,"✅ Done") -> 2 | G6: =COUNTIF('📚 Study Plan'!H:H,"🔄 In Progress") -> 0 | I6: =COUNTIF('📚 Study Plan'!H:H,"⬜ Not Started") -> 174
C8: 📈 OVERALL COMPLETION RATE
C9: =COUNTIF('📚 Study Plan'!H:H,"✅ Done")/176 -> 0.011363636
C11: SECTION-WISE PROGRESS
C12: Section | D12: Topics | E12: Done ✅ | F12: In Progress 🔄 | G12: Paused ⏸ | H12: Skipped ❌ | I12: Remaining ⬜
C13: ASP.NET Core Web API – Basics | D13: 19 | E13: =COUNTIFS('📚 Study Plan'!C:C,C13,'📚 Study Plan'!H:H,"✅ Done") -> 2 | F13: =COUNTIFS('📚 Study Plan'!C:C,C13,'📚 Study Plan'!H:H,"🔄 In Progress") -> 0 | G13: =COUNTIFS('📚 Study Plan'!C:C,C13,'📚 Study Plan'!H:H,"⏸ Paused") -> 0 | H13: =COUNTIFS('📚 Study Plan'!C:C,C13,'📚 Study Plan'!H:H,"❌ Skipped") -> 0 | I13: =D13-E13-F13-G13-H13 -> 17
C14: ASP.NET Core Web API – Routing | D14: 7 | E14: =COUNTIFS('📚 Study Plan'!C:C,C14,'📚 Study Plan'!H:H,"✅ Done") -> 0 | F14: =COUNTIFS('📚 Study Plan'!C:C,C14,'📚 Study Plan'!H:H,"🔄 In Progress") -> 0 | G14: =COUNTIFS('📚 Study Plan'!C:C,C14,'📚 Study Plan'!H:H,"⏸ Paused") -> 0 | H14: =COUNTIFS('📚 Study Plan'!C:C,C14,'📚 Study Plan'!H:H,"❌ Skipped") -> 0 | I14: =D14-E14-F14-G14-H14 -> 7
C15: ASP.NET Core Web API – Return Types and Status Codes | D15: 19 | E15: =COUNTIFS('📚 Study Plan'!C:C,C15,'📚 Study Plan'!H:H,"✅ Done") -> 0 | F15: =COUNTIFS('📚 Study Plan'!C:C,C15,'📚 Study Plan'!H:H,"🔄 In Progress") -> 0 | G15: =COUNTIFS('📚 Study Plan'!C:C,C15,'📚 Study Plan'!H:H,"⏸ Paused") -> 0 | H15: =COUNTIFS('📚 Study Plan'!C:C,C15,'📚 Study Plan'!H:H,"❌ Skipped") -> 0 | I15: =D15-E15-F15-G15-H15 -> 19
C16: ASP.NET Core Web API – Model Binding | D16: 12 | E16: =COUNTIFS('📚 Study Plan'!C:C,C16,'📚 Study Plan'!H:H,"✅ Done") -> 0 | F16: =COUNTIFS('📚 Study Plan'!C:C,C16,'📚 Study Plan'!H:H,"🔄 In Progress") -> 0 | G16: =COUNTIFS('📚 Study Plan'!C:C,C16,'📚 Study Plan'!H:H,"⏸ Paused") -> 0 | H16: =COUNTIFS('📚 Study Plan'!C:C,C16,'📚 Study Plan'!H:H,"❌ Skipped") -> 0 | I16: =D16-E16-F16-G16-H16 -> 12
C17: ASP.NET Core Web API – Entity Framework Core | D17: 17 | E17: =COUNTIFS('📚 Study Plan'!C:C,C17,'📚 Study Plan'!H:H,"✅ Done") -> 0 | F17: =COUNTIFS('📚 Study Plan'!C:C,C17,'📚 Study Plan'!H:H,"🔄 In Progress") -> 0 | G17: =COUNTIFS('📚 Study Plan'!C:C,C17,'📚 Study Plan'!H:H,"⏸ Paused") -> 0 | H17: =COUNTIFS('📚 Study Plan'!C:C,C17,'📚 Study Plan'!H:H,"❌ Skipped") -> 0 | I17: =D17-E17-F17-G17-H17 -> 17
C18: Auto Mapping – ASP.NET Core Web API | D18: 11 | E18: =COUNTIFS('📚 Study Plan'!C:C,C18,'📚 Study Plan'!H:H,"✅ Done") -> 0 | F18: =COUNTIFS('📚 Study Plan'!C:C,C18,'📚 Study Plan'!H:H,"🔄 In Progress") -> 0 | G18: =COUNTIFS('📚 Study Plan'!C:C,C18,'📚 Study Plan'!H:H,"⏸ Paused") -> 0 | H18: =COUNTIFS('📚 Study Plan'!C:C,C18,'📚 Study Plan'!H:H,"❌ Skipped") -> 0 | I18: =D18-E18-F18-G18-H18 -> 11
C19: HTTP Methods in ASP.NET Core Web API | D19: 8 | E19: =COUNTIFS('📚 Study Plan'!C:C,C19,'📚 Study Plan'!H:H,"✅ Done") -> 0 | F19: =COUNTIFS('📚 Study Plan'!C:C,C19,'📚 Study Plan'!H:H,"🔄 In Progress") -> 0 | G19: =COUNTIFS('📚 Study Plan'!C:C,C19,'📚 Study Plan'!H:H,"⏸ Paused") -> 0 | H19: =COUNTIFS('📚 Study Plan'!C:C,C19,'📚 Study Plan'!H:H,"❌ Skipped") -> 0 | I19: =D19-E19-F19-G19-H19 -> 8
C20: Logging – ASP.NET Core Web API | D20: 7 | E20: =COUNTIFS('📚 Study Plan'!C:C,C20,'📚 Study Plan'!H:H,"✅ Done") -> 0 | F20: =COUNTIFS('📚 Study Plan'!C:C,C20,'📚 Study Plan'!H:H,"🔄 In Progress") -> 0 | G20: =COUNTIFS('📚 Study Plan'!C:C,C20,'📚 Study Plan'!H:H,"⏸ Paused") -> 0 | H20: =COUNTIFS('📚 Study Plan'!C:C,C20,'📚 Study Plan'!H:H,"❌ Skipped") -> 0 | I20: =D20-E20-F20-G20-H20 -> 7
C21: Caching – ASP.NET Core Web API | D21: 9 | E21: =COUNTIFS('📚 Study Plan'!C:C,C21,'📚 Study Plan'!H:H,"✅ Done") -> 0 | F21: =COUNTIFS('📚 Study Plan'!C:C,C21,'📚 Study Plan'!H:H,"🔄 In Progress") -> 0 | G21: =COUNTIFS('📚 Study Plan'!C:C,C21,'📚 Study Plan'!H:H,"⏸ Paused") -> 0 | H21: =COUNTIFS('📚 Study Plan'!C:C,C21,'📚 Study Plan'!H:H,"❌ Skipped") -> 0 | I21: =D21-E21-F21-G21-H21 -> 9
C22: Fluent Validations – ASP.NET Core Web API | D22: 5 | E22: =COUNTIFS('📚 Study Plan'!C:C,C22,'📚 Study Plan'!H:H,"✅ Done") -> 0 | F22: =COUNTIFS('📚 Study Plan'!C:C,C22,'📚 Study Plan'!H:H,"🔄 In Progress") -> 0 | G22: =COUNTIFS('📚 Study Plan'!C:C,C22,'📚 Study Plan'!H:H,"⏸ Paused") -> 0 | H22: =COUNTIFS('📚 Study Plan'!C:C,C22,'📚 Study Plan'!H:H,"❌ Skipped") -> 0 | I22: =D22-E22-F22-G22-H22 -> 5
C23: Filters – ASP.NET Core Web API | D23: 9 | E23: =COUNTIFS('📚 Study Plan'!C:C,C23,'📚 Study Plan'!H:H,"✅ Done") -> 0 | F23: =COUNTIFS('📚 Study Plan'!C:C,C23,'📚 Study Plan'!H:H,"🔄 In Progress") -> 0 | G23: =COUNTIFS('📚 Study Plan'!C:C,C23,'📚 Study Plan'!H:H,"⏸ Paused") -> 0 | H23: =COUNTIFS('📚 Study Plan'!C:C,C23,'📚 Study Plan'!H:H,"❌ Skipped") -> 0 | I23: =D23-E23-F23-G23-H23 -> 9
C24: Security – ASP.NET Core Web API | D24: 14 | E24: =COUNTIFS('📚 Study Plan'!C:C,C24,'📚 Study Plan'!H:H,"✅ Done") -> 0 | F24: =COUNTIFS('📚 Study Plan'!C:C,C24,'📚 Study Plan'!H:H,"🔄 In Progress") -> 0 | G24: =COUNTIFS('📚 Study Plan'!C:C,C24,'📚 Study Plan'!H:H,"⏸ Paused") -> 0 | H24: =COUNTIFS('📚 Study Plan'!C:C,C24,'📚 Study Plan'!H:H,"❌ Skipped") -> 0 | I24: =D24-E24-F24-G24-H24 -> 14
... C30: ASP.NET Core Web API – Advanced Concepts | D30: 6 | E30: =COUNTIFS('📚 Study Plan'!C:C,C30,'📚 Study Plan'!H:H,"✅ Done") -> 0 | F30: =COUNTIFS('📚 Study Plan'!C:C,C30,'📚 Study Plan'!H:H,"🔄 In Progress") -> 0 | G30: =COUNTIFS('📚 Study Plan'!C:C,C30,'📚 Study Plan'!H:H,"⏸ Paused") -> 0 | H30: =COUNTIFS('📚 Study Plan'!C:C,C30,'📚 Study Plan'!H:H,"❌ Skipped") -> 0 | I30: =D30-E30-F30-G30-H30 -> 6
C31: TOTAL | D31: =SUM(D13:D30) -> 176 | E31: =SUM(E13:E30) -> 2 | F31: =SUM(F13:F30) -> 0 | G31: =SUM(G13:G30) -> 0 | H31: =SUM(H13:H30) -> 0 | I31: =SUM(I13:I30) -> 174
C33: 💡 Update Status in '📚 Study Plan' sheet → Dashboard auto-refreshes | 5 Topics/Day → Complete in just 36 days!

Sheet 📋 Sections Overview
A1: 📋 All Sections at a Glance
B2: Section | C2: Topics | D2: Days Needed | E2: Topic Range
B3: ASP.NET Core Web API – Basics | C3: 19 | D3: 4 | E3: Topic 1 – 19
B4: ASP.NET Core Web API – Routing | C4: 7 | D4: 2 | E4: Topic 20 – 26
B5: ASP.NET Core Web API – Return Types and Status Codes | C5: 19 | D5: 4 | E5: Topic 27 – 45
B6: ASP.NET Core Web API – Model Binding | C6: 12 | D6: 3 | E6: Topic 46 – 57
B7: ASP.NET Core Web API – Entity Framework Core | C7: 17 | D7: 4 | E7: Topic 58 – 74
B8: Auto Mapping – ASP.NET Core Web API | C8: 11 | D8: 3 | E8: Topic 75 – 85
B9: HTTP Methods in ASP.NET Core Web API | C9: 8 | D9: 2 | E9: Topic 86 – 93
B10: Logging – ASP.NET Core Web API | C10: 7 | D10: 2 | E10: Topic 94 – 100
B11: Caching – ASP.NET Core Web API | C11: 9 | D11: 2 | E11: Topic 101 – 109
B12: Fluent Validations – ASP.NET Core Web API | C12: 5 | D12: 1 | E12: Topic 110 – 114
B13: Filters – ASP.NET Core Web API | C13: 9 | D13: 2 | E13: Topic 115 – 123
B14: Security – ASP.NET Core Web API | C14: 14 | D14: 3 | E14: Topic 124 – 137
... B20: ASP.NET Core Web API – Advanced Concepts | C20: 6 | D20: 2 | E20: Topic 171 – 176
B21: TOTAL | C21: 176 | D21: 36
